2020-04-07 13:38:40,962 INFO: errors [in C:/Users/jrile/Desktop/Software Engineering/HelpInPT/flask-boilerplate/app.py:912]
2020-04-07 13:42:49,477 ERROR: Exception on /section/12345/1/None [GET] [in C:\Users\jrile\AppData\Local\Programs\Python\Python38\lib\site-packages\flask\app.py:1890]
Traceback (most recent call last):
  File "C:\Users\jrile\AppData\Local\Programs\Python\Python38\lib\site-packages\flask\app.py", line 2446, in wsgi_app
    response = self.full_dispatch_request()
  File "C:\Users\jrile\AppData\Local\Programs\Python\Python38\lib\site-packages\flask\app.py", line 1951, in full_dispatch_request
    rv = self.handle_user_exception(e)
  File "C:\Users\jrile\AppData\Local\Programs\Python\Python38\lib\site-packages\flask\app.py", line 1820, in handle_user_exception
    reraise(exc_type, exc_value, tb)
  File "C:\Users\jrile\AppData\Local\Programs\Python\Python38\lib\site-packages\flask\_compat.py", line 39, in reraise
    raise value
  File "C:\Users\jrile\AppData\Local\Programs\Python\Python38\lib\site-packages\flask\app.py", line 1949, in full_dispatch_request
    rv = self.dispatch_request()
  File "C:\Users\jrile\AppData\Local\Programs\Python\Python38\lib\site-packages\flask\app.py", line 1935, in dispatch_request
    return self.view_functions[rule.endpoint](**req.view_args)
  File "C:\Users\jrile\AppData\Local\Programs\Python\Python38\lib\site-packages\flask_login\utils.py", line 272, in decorated_view
    return func(*args, **kwargs)
  File "C:/Users/jrile/Desktop/Software Engineering/HelpInPT/flask-boilerplate/app.py", line 555, in section_page
    section_name = section_name[2]
TypeError: 'NoneType' object is not subscriptable
2020-04-07 13:43:08,877 ERROR: Exception on /glossary/12345 [GET] [in C:\Users\jrile\AppData\Local\Programs\Python\Python38\lib\site-packages\flask\app.py:1890]
Traceback (most recent call last):
  File "C:\Users\jrile\AppData\Local\Programs\Python\Python38\lib\site-packages\flask\app.py", line 2446, in wsgi_app
    response = self.full_dispatch_request()
  File "C:\Users\jrile\AppData\Local\Programs\Python\Python38\lib\site-packages\flask\app.py", line 1951, in full_dispatch_request
    rv = self.handle_user_exception(e)
  File "C:\Users\jrile\AppData\Local\Programs\Python\Python38\lib\site-packages\flask\app.py", line 1820, in handle_user_exception
    reraise(exc_type, exc_value, tb)
  File "C:\Users\jrile\AppData\Local\Programs\Python\Python38\lib\site-packages\flask\_compat.py", line 39, in reraise
    raise value
  File "C:\Users\jrile\AppData\Local\Programs\Python\Python38\lib\site-packages\flask\app.py", line 1949, in full_dispatch_request
    rv = self.dispatch_request()
  File "C:\Users\jrile\AppData\Local\Programs\Python\Python38\lib\site-packages\flask\app.py", line 1935, in dispatch_request
    return self.view_functions[rule.endpoint](**req.view_args)
  File "C:\Users\jrile\AppData\Local\Programs\Python\Python38\lib\site-packages\flask_login\utils.py", line 272, in decorated_view
    return func(*args, **kwargs)
  File "C:/Users/jrile/Desktop/Software Engineering/HelpInPT/flask-boilerplate/app.py", line 714, in glossaryTemplate
    temp = query_db('SELECT * from GlossaryImages WHERE termID = "%s"' % str(ids[y]))
  File "C:/Users/jrile/Desktop/Software Engineering/HelpInPT/flask-boilerplate/app.py", line 61, in query_db
    cur = get_db().execute(query, args)
sqlite3.OperationalError: no such table: GlossaryImages
2020-04-07 14:15:58,427 ERROR: Exception on /section/12345/1/None [GET] [in C:\Users\jrile\AppData\Local\Programs\Python\Python38\lib\site-packages\flask\app.py:1890]
Traceback (most recent call last):
  File "C:\Users\jrile\AppData\Local\Programs\Python\Python38\lib\site-packages\flask\app.py", line 2446, in wsgi_app
    response = self.full_dispatch_request()
  File "C:\Users\jrile\AppData\Local\Programs\Python\Python38\lib\site-packages\flask\app.py", line 1951, in full_dispatch_request
    rv = self.handle_user_exception(e)
  File "C:\Users\jrile\AppData\Local\Programs\Python\Python38\lib\site-packages\flask\app.py", line 1820, in handle_user_exception
    reraise(exc_type, exc_value, tb)
  File "C:\Users\jrile\AppData\Local\Programs\Python\Python38\lib\site-packages\flask\_compat.py", line 39, in reraise
    raise value
  File "C:\Users\jrile\AppData\Local\Programs\Python\Python38\lib\site-packages\flask\app.py", line 1949, in full_dispatch_request
    rv = self.dispatch_request()
  File "C:\Users\jrile\AppData\Local\Programs\Python\Python38\lib\site-packages\flask\app.py", line 1935, in dispatch_request
    return self.view_functions[rule.endpoint](**req.view_args)
  File "C:\Users\jrile\AppData\Local\Programs\Python\Python38\lib\site-packages\flask_login\utils.py", line 272, in decorated_view
    return func(*args, **kwargs)
  File "C:/Users/jrile/Desktop/Software Engineering/HelpInPT/flask-boilerplate/app.py", line 555, in section_page
    section_name = section_name[2]
TypeError: 'NoneType' object is not subscriptable
2020-04-07 14:23:37,299 ERROR: Exception on /section/12345/1/None [GET] [in C:\Users\jrile\AppData\Local\Programs\Python\Python38\lib\site-packages\flask\app.py:1890]
Traceback (most recent call last):
  File "C:\Users\jrile\AppData\Local\Programs\Python\Python38\lib\site-packages\flask\app.py", line 2446, in wsgi_app
    response = self.full_dispatch_request()
  File "C:\Users\jrile\AppData\Local\Programs\Python\Python38\lib\site-packages\flask\app.py", line 1951, in full_dispatch_request
    rv = self.handle_user_exception(e)
  File "C:\Users\jrile\AppData\Local\Programs\Python\Python38\lib\site-packages\flask\app.py", line 1820, in handle_user_exception
    reraise(exc_type, exc_value, tb)
  File "C:\Users\jrile\AppData\Local\Programs\Python\Python38\lib\site-packages\flask\_compat.py", line 39, in reraise
    raise value
  File "C:\Users\jrile\AppData\Local\Programs\Python\Python38\lib\site-packages\flask\app.py", line 1949, in full_dispatch_request
    rv = self.dispatch_request()
  File "C:\Users\jrile\AppData\Local\Programs\Python\Python38\lib\site-packages\flask\app.py", line 1935, in dispatch_request
    return self.view_functions[rule.endpoint](**req.view_args)
  File "C:\Users\jrile\AppData\Local\Programs\Python\Python38\lib\site-packages\flask_login\utils.py", line 272, in decorated_view
    return func(*args, **kwargs)
  File "C:/Users/jrile/Desktop/Software Engineering/HelpInPT/flask-boilerplate/app.py", line 555, in section_page
    section_name = section_name[2]
TypeError: 'NoneType' object is not subscriptable
2020-04-07 16:05:23,487 INFO: errors [in C:/Users/jrile/Desktop/Software Engineering/HelpInPT/flask-boilerplate/app.py:913]
2020-04-07 16:11:41,367 INFO: errors [in C:/Users/jrile/Desktop/Software Engineering/HelpInPT/flask-boilerplate/app.py:913]
2020-04-07 16:12:56,692 INFO: errors [in C:/Users/jrile/Desktop/Software Engineering/HelpInPT/flask-boilerplate/app.py:913]
2020-04-07 18:18:07,884 INFO: errors [in C:/Users/jrile/Desktop/Software Engineering/HelpInPT/flask-boilerplate/app.py:913]
2020-04-07 18:20:15,262 INFO: errors [in C:/Users/jrile/Desktop/Software Engineering/HelpInPT/flask-boilerplate/app.py:913]
2020-04-07 18:22:19,695 INFO: errors [in C:/Users/jrile/Desktop/Software Engineering/HelpInPT/flask-boilerplate/app.py:913]
2020-04-07 18:22:53,688 ERROR: Exception on /section/12345/1/None [GET] [in C:\Users\jrile\AppData\Local\Programs\Python\Python38\lib\site-packages\flask\app.py:1890]
Traceback (most recent call last):
  File "C:\Users\jrile\AppData\Local\Programs\Python\Python38\lib\site-packages\flask\app.py", line 2446, in wsgi_app
    response = self.full_dispatch_request()
  File "C:\Users\jrile\AppData\Local\Programs\Python\Python38\lib\site-packages\flask\app.py", line 1951, in full_dispatch_request
    rv = self.handle_user_exception(e)
  File "C:\Users\jrile\AppData\Local\Programs\Python\Python38\lib\site-packages\flask\app.py", line 1820, in handle_user_exception
    reraise(exc_type, exc_value, tb)
  File "C:\Users\jrile\AppData\Local\Programs\Python\Python38\lib\site-packages\flask\_compat.py", line 39, in reraise
    raise value
  File "C:\Users\jrile\AppData\Local\Programs\Python\Python38\lib\site-packages\flask\app.py", line 1949, in full_dispatch_request
    rv = self.dispatch_request()
  File "C:\Users\jrile\AppData\Local\Programs\Python\Python38\lib\site-packages\flask\app.py", line 1935, in dispatch_request
    return self.view_functions[rule.endpoint](**req.view_args)
  File "C:\Users\jrile\AppData\Local\Programs\Python\Python38\lib\site-packages\flask_login\utils.py", line 272, in decorated_view
    return func(*args, **kwargs)
  File "C:/Users/jrile/Desktop/Software Engineering/HelpInPT/flask-boilerplate/app.py", line 556, in section_page
    section_name = section_name[2]
TypeError: 'NoneType' object is not subscriptable
2020-04-07 18:23:35,260 ERROR: Exception on /section/12345/1/None [GET] [in C:\Users\jrile\AppData\Local\Programs\Python\Python38\lib\site-packages\flask\app.py:1890]
Traceback (most recent call last):
  File "C:\Users\jrile\AppData\Local\Programs\Python\Python38\lib\site-packages\flask\app.py", line 2446, in wsgi_app
    response = self.full_dispatch_request()
  File "C:\Users\jrile\AppData\Local\Programs\Python\Python38\lib\site-packages\flask\app.py", line 1951, in full_dispatch_request
    rv = self.handle_user_exception(e)
  File "C:\Users\jrile\AppData\Local\Programs\Python\Python38\lib\site-packages\flask\app.py", line 1820, in handle_user_exception
    reraise(exc_type, exc_value, tb)
  File "C:\Users\jrile\AppData\Local\Programs\Python\Python38\lib\site-packages\flask\_compat.py", line 39, in reraise
    raise value
  File "C:\Users\jrile\AppData\Local\Programs\Python\Python38\lib\site-packages\flask\app.py", line 1949, in full_dispatch_request
    rv = self.dispatch_request()
  File "C:\Users\jrile\AppData\Local\Programs\Python\Python38\lib\site-packages\flask\app.py", line 1935, in dispatch_request
    return self.view_functions[rule.endpoint](**req.view_args)
  File "C:\Users\jrile\AppData\Local\Programs\Python\Python38\lib\site-packages\flask_login\utils.py", line 272, in decorated_view
    return func(*args, **kwargs)
  File "C:/Users/jrile/Desktop/Software Engineering/HelpInPT/flask-boilerplate/app.py", line 556, in section_page
    section_name = section_name[2]
TypeError: 'NoneType' object is not subscriptable
2020-04-07 18:36:21,619 INFO: errors [in C:/Users/jrile/Desktop/Software Engineering/HelpInPT/flask-boilerplate/app.py:917]
2020-04-07 18:36:49,396 ERROR: Exception on /student-class-overview/12345 [GET] [in C:\Users\jrile\AppData\Local\Programs\Python\Python38\lib\site-packages\flask\app.py:1890]
Traceback (most recent call last):
  File "C:\Users\jrile\AppData\Local\Programs\Python\Python38\lib\site-packages\flask\app.py", line 2446, in wsgi_app
    response = self.full_dispatch_request()
  File "C:\Users\jrile\AppData\Local\Programs\Python\Python38\lib\site-packages\flask\app.py", line 1951, in full_dispatch_request
    rv = self.handle_user_exception(e)
  File "C:\Users\jrile\AppData\Local\Programs\Python\Python38\lib\site-packages\flask\app.py", line 1820, in handle_user_exception
    reraise(exc_type, exc_value, tb)
  File "C:\Users\jrile\AppData\Local\Programs\Python\Python38\lib\site-packages\flask\_compat.py", line 39, in reraise
    raise value
  File "C:\Users\jrile\AppData\Local\Programs\Python\Python38\lib\site-packages\flask\app.py", line 1949, in full_dispatch_request
    rv = self.dispatch_request()
  File "C:\Users\jrile\AppData\Local\Programs\Python\Python38\lib\site-packages\flask\app.py", line 1935, in dispatch_request
    return self.view_functions[rule.endpoint](**req.view_args)
  File "C:\Users\jrile\AppData\Local\Programs\Python\Python38\lib\site-packages\flask_login\utils.py", line 272, in decorated_view
    return func(*args, **kwargs)
  File "C:\Users\jrile\AppData\Local\Programs\Python\Python38\lib\site-packages\flask_user\decorators.py", line 143, in decorator
    return view_function(*args, **kwargs)
  File "C:/Users/jrile/Desktop/Software Engineering/HelpInPT/flask-boilerplate/app.py", line 877, in student_class_home
    this_user_class = UserClasses.query.filter(and_(email=current_user.id, classID=classID)).first()
TypeError: and_() got an unexpected keyword argument 'email'
2020-04-07 18:38:06,002 INFO: errors [in C:/Users/jrile/Desktop/Software Engineering/HelpInPT/flask-boilerplate/app.py:917]
2020-04-07 18:38:22,761 ERROR: Exception on /student-class-overview/12345 [GET] [in C:\Users\jrile\AppData\Local\Programs\Python\Python38\lib\site-packages\flask\app.py:1890]
Traceback (most recent call last):
  File "C:\Users\jrile\AppData\Local\Programs\Python\Python38\lib\site-packages\flask\app.py", line 2446, in wsgi_app
    response = self.full_dispatch_request()
  File "C:\Users\jrile\AppData\Local\Programs\Python\Python38\lib\site-packages\flask\app.py", line 1951, in full_dispatch_request
    rv = self.handle_user_exception(e)
  File "C:\Users\jrile\AppData\Local\Programs\Python\Python38\lib\site-packages\flask\app.py", line 1820, in handle_user_exception
    reraise(exc_type, exc_value, tb)
  File "C:\Users\jrile\AppData\Local\Programs\Python\Python38\lib\site-packages\flask\_compat.py", line 39, in reraise
    raise value
  File "C:\Users\jrile\AppData\Local\Programs\Python\Python38\lib\site-packages\flask\app.py", line 1949, in full_dispatch_request
    rv = self.dispatch_request()
  File "C:\Users\jrile\AppData\Local\Programs\Python\Python38\lib\site-packages\flask\app.py", line 1935, in dispatch_request
    return self.view_functions[rule.endpoint](**req.view_args)
  File "C:\Users\jrile\AppData\Local\Programs\Python\Python38\lib\site-packages\flask_login\utils.py", line 272, in decorated_view
    return func(*args, **kwargs)
  File "C:\Users\jrile\AppData\Local\Programs\Python\Python38\lib\site-packages\flask_user\decorators.py", line 143, in decorator
    return view_function(*args, **kwargs)
  File "C:/Users/jrile/Desktop/Software Engineering/HelpInPT/flask-boilerplate/app.py", line 877, in student_class_home
    this_user_class = UserClasses.query.filter(and_(current_user.id, classID)).first()
  File "<string>", line 2, in and_
  File "C:\Users\jrile\AppData\Local\Programs\Python\Python38\lib\site-packages\sqlalchemy\sql\elements.py", line 2098, in and_
    return cls._construct(operators.and_, True_, False_, *clauses)
  File "C:\Users\jrile\AppData\Local\Programs\Python\Python38\lib\site-packages\sqlalchemy\sql\elements.py", line 2028, in _construct
    clauses = [
  File "C:\Users\jrile\AppData\Local\Programs\Python\Python38\lib\site-packages\sqlalchemy\sql\elements.py", line 2029, in <listcomp>
    _expression_literal_as_text(clause)
  File "C:\Users\jrile\AppData\Local\Programs\Python\Python38\lib\site-packages\sqlalchemy\sql\elements.py", line 4569, in _expression_literal_as_text
    return _literal_as_text(element)
  File "C:\Users\jrile\AppData\Local\Programs\Python\Python38\lib\site-packages\sqlalchemy\sql\elements.py", line 4592, in _literal_as_text
    return _literal_as(element, _no_text_coercion)
  File "C:\Users\jrile\AppData\Local\Programs\Python\Python38\lib\site-packages\sqlalchemy\sql\elements.py", line 4578, in _literal_as
    return text_fallback(element)
  File "C:\Users\jrile\AppData\Local\Programs\Python\Python38\lib\site-packages\sqlalchemy\sql\elements.py", line 4617, in _no_text_coercion
    raise exc_cls(
sqlalchemy.exc.ArgumentError: Textual SQL expression 'student1@gmail.com' should be explicitly declared as text('student1@gmail.com')
2020-04-07 18:39:22,447 INFO: errors [in C:/Users/jrile/Desktop/Software Engineering/HelpInPT/flask-boilerplate/app.py:917]
2020-04-07 18:39:25,335 ERROR: Exception on /student-class-overview/12345 [GET] [in C:\Users\jrile\AppData\Local\Programs\Python\Python38\lib\site-packages\flask\app.py:1890]
Traceback (most recent call last):
  File "C:\Users\jrile\AppData\Local\Programs\Python\Python38\lib\site-packages\sqlalchemy\engine\base.py", line 1245, in _execute_context
    self.dialect.do_execute(
  File "C:\Users\jrile\AppData\Local\Programs\Python\Python38\lib\site-packages\sqlalchemy\engine\default.py", line 588, in do_execute
    cursor.execute(statement, parameters)
sqlite3.OperationalError: near "@gmail": syntax error

The above exception was the direct cause of the following exception:

Traceback (most recent call last):
  File "C:\Users\jrile\AppData\Local\Programs\Python\Python38\lib\site-packages\flask\app.py", line 2446, in wsgi_app
    response = self.full_dispatch_request()
  File "C:\Users\jrile\AppData\Local\Programs\Python\Python38\lib\site-packages\flask\app.py", line 1951, in full_dispatch_request
    rv = self.handle_user_exception(e)
  File "C:\Users\jrile\AppData\Local\Programs\Python\Python38\lib\site-packages\flask\app.py", line 1820, in handle_user_exception
    reraise(exc_type, exc_value, tb)
  File "C:\Users\jrile\AppData\Local\Programs\Python\Python38\lib\site-packages\flask\_compat.py", line 39, in reraise
    raise value
  File "C:\Users\jrile\AppData\Local\Programs\Python\Python38\lib\site-packages\flask\app.py", line 1949, in full_dispatch_request
    rv = self.dispatch_request()
  File "C:\Users\jrile\AppData\Local\Programs\Python\Python38\lib\site-packages\flask\app.py", line 1935, in dispatch_request
    return self.view_functions[rule.endpoint](**req.view_args)
  File "C:\Users\jrile\AppData\Local\Programs\Python\Python38\lib\site-packages\flask_login\utils.py", line 272, in decorated_view
    return func(*args, **kwargs)
  File "C:\Users\jrile\AppData\Local\Programs\Python\Python38\lib\site-packages\flask_user\decorators.py", line 143, in decorator
    return view_function(*args, **kwargs)
  File "C:/Users/jrile/Desktop/Software Engineering/HelpInPT/flask-boilerplate/app.py", line 877, in student_class_home
    this_user_class = UserClasses.query.filter(and_(text(current_user.id), text(classID))).first()
  File "C:\Users\jrile\AppData\Local\Programs\Python\Python38\lib\site-packages\sqlalchemy\orm\query.py", line 3287, in first
    ret = list(self[0:1])
  File "C:\Users\jrile\AppData\Local\Programs\Python\Python38\lib\site-packages\sqlalchemy\orm\query.py", line 3065, in __getitem__
    return list(res)
  File "C:\Users\jrile\AppData\Local\Programs\Python\Python38\lib\site-packages\sqlalchemy\orm\query.py", line 3389, in __iter__
    return self._execute_and_instances(context)
  File "C:\Users\jrile\AppData\Local\Programs\Python\Python38\lib\site-packages\sqlalchemy\orm\query.py", line 3414, in _execute_and_instances
    result = conn.execute(querycontext.statement, self._params)
  File "C:\Users\jrile\AppData\Local\Programs\Python\Python38\lib\site-packages\sqlalchemy\engine\base.py", line 982, in execute
    return meth(self, multiparams, params)
  File "C:\Users\jrile\AppData\Local\Programs\Python\Python38\lib\site-packages\sqlalchemy\sql\elements.py", line 293, in _execute_on_connection
    return connection._execute_clauseelement(self, multiparams, params)
  File "C:\Users\jrile\AppData\Local\Programs\Python\Python38\lib\site-packages\sqlalchemy\engine\base.py", line 1095, in _execute_clauseelement
    ret = self._execute_context(
  File "C:\Users\jrile\AppData\Local\Programs\Python\Python38\lib\site-packages\sqlalchemy\engine\base.py", line 1249, in _execute_context
    self._handle_dbapi_exception(
  File "C:\Users\jrile\AppData\Local\Programs\Python\Python38\lib\site-packages\sqlalchemy\engine\base.py", line 1476, in _handle_dbapi_exception
    util.raise_from_cause(sqlalchemy_exception, exc_info)
  File "C:\Users\jrile\AppData\Local\Programs\Python\Python38\lib\site-packages\sqlalchemy\util\compat.py", line 398, in raise_from_cause
    reraise(type(exception), exception, tb=exc_tb, cause=cause)
  File "C:\Users\jrile\AppData\Local\Programs\Python\Python38\lib\site-packages\sqlalchemy\util\compat.py", line 152, in reraise
    raise value.with_traceback(tb)
  File "C:\Users\jrile\AppData\Local\Programs\Python\Python38\lib\site-packages\sqlalchemy\engine\base.py", line 1245, in _execute_context
    self.dialect.do_execute(
  File "C:\Users\jrile\AppData\Local\Programs\Python\Python38\lib\site-packages\sqlalchemy\engine\default.py", line 588, in do_execute
    cursor.execute(statement, parameters)
sqlalchemy.exc.OperationalError: (sqlite3.OperationalError) near "@gmail": syntax error
[SQL: SELECT "Enroll".email AS "Enroll_email", "Enroll"."classID" AS "Enroll_classID", "Enroll"."lastSectionID" AS "Enroll_lastSectionID" 
FROM "Enroll" 
WHERE student1@gmail.com AND 12345
 LIMIT ? OFFSET ?]
[parameters: (1, 0)]
(Background on this error at: http://sqlalche.me/e/e3q8)
2020-04-07 18:44:22,033 INFO: errors [in C:/Users/jrile/Desktop/Software Engineering/HelpInPT/flask-boilerplate/app.py:916]
2020-04-07 18:44:26,641 ERROR: Exception on /student-class-overview/12345 [GET] [in C:\Users\jrile\AppData\Local\Programs\Python\Python38\lib\site-packages\flask\app.py:1890]
Traceback (most recent call last):
  File "C:\Users\jrile\AppData\Local\Programs\Python\Python38\lib\site-packages\flask\app.py", line 2446, in wsgi_app
    response = self.full_dispatch_request()
  File "C:\Users\jrile\AppData\Local\Programs\Python\Python38\lib\site-packages\flask\app.py", line 1951, in full_dispatch_request
    rv = self.handle_user_exception(e)
  File "C:\Users\jrile\AppData\Local\Programs\Python\Python38\lib\site-packages\flask\app.py", line 1820, in handle_user_exception
    reraise(exc_type, exc_value, tb)
  File "C:\Users\jrile\AppData\Local\Programs\Python\Python38\lib\site-packages\flask\_compat.py", line 39, in reraise
    raise value
  File "C:\Users\jrile\AppData\Local\Programs\Python\Python38\lib\site-packages\flask\app.py", line 1949, in full_dispatch_request
    rv = self.dispatch_request()
  File "C:\Users\jrile\AppData\Local\Programs\Python\Python38\lib\site-packages\flask\app.py", line 1935, in dispatch_request
    return self.view_functions[rule.endpoint](**req.view_args)
  File "C:\Users\jrile\AppData\Local\Programs\Python\Python38\lib\site-packages\flask_login\utils.py", line 272, in decorated_view
    return func(*args, **kwargs)
  File "C:\Users\jrile\AppData\Local\Programs\Python\Python38\lib\site-packages\flask_user\decorators.py", line 143, in decorator
    return view_function(*args, **kwargs)
  File "C:/Users/jrile/Desktop/Software Engineering/HelpInPT/flask-boilerplate/app.py", line 878, in student_class_home
    last_chapter_ID = query_db("SELECT * from Sections where id='%s'" % last_section_ID)[1]
  File "C:/Users/jrile/Desktop/Software Engineering/HelpInPT/flask-boilerplate/app.py", line 62, in query_db
    cur = get_db().execute(query, args)
sqlite3.OperationalError: no such column: id
2020-04-07 18:45:19,604 INFO: errors [in C:/Users/jrile/Desktop/Software Engineering/HelpInPT/flask-boilerplate/app.py:916]
2020-04-07 18:45:22,784 ERROR: Exception on /student-class-overview/12345 [GET] [in C:\Users\jrile\AppData\Local\Programs\Python\Python38\lib\site-packages\flask\app.py:1890]
Traceback (most recent call last):
  File "C:\Users\jrile\AppData\Local\Programs\Python\Python38\lib\site-packages\flask\app.py", line 2446, in wsgi_app
    response = self.full_dispatch_request()
  File "C:\Users\jrile\AppData\Local\Programs\Python\Python38\lib\site-packages\flask\app.py", line 1951, in full_dispatch_request
    rv = self.handle_user_exception(e)
  File "C:\Users\jrile\AppData\Local\Programs\Python\Python38\lib\site-packages\flask\app.py", line 1820, in handle_user_exception
    reraise(exc_type, exc_value, tb)
  File "C:\Users\jrile\AppData\Local\Programs\Python\Python38\lib\site-packages\flask\_compat.py", line 39, in reraise
    raise value
  File "C:\Users\jrile\AppData\Local\Programs\Python\Python38\lib\site-packages\flask\app.py", line 1949, in full_dispatch_request
    rv = self.dispatch_request()
  File "C:\Users\jrile\AppData\Local\Programs\Python\Python38\lib\site-packages\flask\app.py", line 1935, in dispatch_request
    return self.view_functions[rule.endpoint](**req.view_args)
  File "C:\Users\jrile\AppData\Local\Programs\Python\Python38\lib\site-packages\flask_login\utils.py", line 272, in decorated_view
    return func(*args, **kwargs)
  File "C:\Users\jrile\AppData\Local\Programs\Python\Python38\lib\site-packages\flask_user\decorators.py", line 143, in decorator
    return view_function(*args, **kwargs)
  File "C:/Users/jrile/Desktop/Software Engineering/HelpInPT/flask-boilerplate/app.py", line 878, in student_class_home
    last_chapter_ID = query_db("SELECT * from Sections where sectionID='%s'" % last_section_ID)[1]
IndexError: list index out of range
2020-04-07 18:46:09,107 INFO: errors [in C:/Users/jrile/Desktop/Software Engineering/HelpInPT/flask-boilerplate/app.py:917]
2020-04-07 18:46:50,663 INFO: errors [in C:/Users/jrile/Desktop/Software Engineering/HelpInPT/flask-boilerplate/app.py:917]
2020-04-07 18:47:17,623 INFO: errors [in C:/Users/jrile/Desktop/Software Engineering/HelpInPT/flask-boilerplate/app.py:917]
2020-04-07 18:47:59,071 INFO: errors [in C:/Users/jrile/Desktop/Software Engineering/HelpInPT/flask-boilerplate/app.py:918]
2020-04-07 18:49:38,149 INFO: errors [in C:/Users/jrile/Desktop/Software Engineering/HelpInPT/flask-boilerplate/app.py:918]
2020-04-07 18:49:44,962 ERROR: Exception on /section/12345/1/None [GET] [in C:\Users\jrile\AppData\Local\Programs\Python\Python38\lib\site-packages\flask\app.py:1890]
Traceback (most recent call last):
  File "C:\Users\jrile\AppData\Local\Programs\Python\Python38\lib\site-packages\flask\app.py", line 2446, in wsgi_app
    response = self.full_dispatch_request()
  File "C:\Users\jrile\AppData\Local\Programs\Python\Python38\lib\site-packages\flask\app.py", line 1951, in full_dispatch_request
    rv = self.handle_user_exception(e)
  File "C:\Users\jrile\AppData\Local\Programs\Python\Python38\lib\site-packages\flask\app.py", line 1820, in handle_user_exception
    reraise(exc_type, exc_value, tb)
  File "C:\Users\jrile\AppData\Local\Programs\Python\Python38\lib\site-packages\flask\_compat.py", line 39, in reraise
    raise value
  File "C:\Users\jrile\AppData\Local\Programs\Python\Python38\lib\site-packages\flask\app.py", line 1949, in full_dispatch_request
    rv = self.dispatch_request()
  File "C:\Users\jrile\AppData\Local\Programs\Python\Python38\lib\site-packages\flask\app.py", line 1935, in dispatch_request
    return self.view_functions[rule.endpoint](**req.view_args)
  File "C:\Users\jrile\AppData\Local\Programs\Python\Python38\lib\site-packages\flask_login\utils.py", line 272, in decorated_view
    return func(*args, **kwargs)
  File "C:/Users/jrile/Desktop/Software Engineering/HelpInPT/flask-boilerplate/app.py", line 557, in section_page
    section_name = section_name[2]
TypeError: 'NoneType' object is not subscriptable
2020-04-07 18:50:32,556 ERROR: Exception on /section/12345/1/None [GET] [in C:\Users\jrile\AppData\Local\Programs\Python\Python38\lib\site-packages\flask\app.py:1890]
Traceback (most recent call last):
  File "C:\Users\jrile\AppData\Local\Programs\Python\Python38\lib\site-packages\flask\app.py", line 2446, in wsgi_app
    response = self.full_dispatch_request()
  File "C:\Users\jrile\AppData\Local\Programs\Python\Python38\lib\site-packages\flask\app.py", line 1951, in full_dispatch_request
    rv = self.handle_user_exception(e)
  File "C:\Users\jrile\AppData\Local\Programs\Python\Python38\lib\site-packages\flask\app.py", line 1820, in handle_user_exception
    reraise(exc_type, exc_value, tb)
  File "C:\Users\jrile\AppData\Local\Programs\Python\Python38\lib\site-packages\flask\_compat.py", line 39, in reraise
    raise value
  File "C:\Users\jrile\AppData\Local\Programs\Python\Python38\lib\site-packages\flask\app.py", line 1949, in full_dispatch_request
    rv = self.dispatch_request()
  File "C:\Users\jrile\AppData\Local\Programs\Python\Python38\lib\site-packages\flask\app.py", line 1935, in dispatch_request
    return self.view_functions[rule.endpoint](**req.view_args)
  File "C:\Users\jrile\AppData\Local\Programs\Python\Python38\lib\site-packages\flask_login\utils.py", line 272, in decorated_view
    return func(*args, **kwargs)
  File "C:/Users/jrile/Desktop/Software Engineering/HelpInPT/flask-boilerplate/app.py", line 557, in section_page
    section_name = section_name[2]
TypeError: 'NoneType' object is not subscriptable
2020-04-07 18:51:03,653 ERROR: Exception on /section/12345/1/None [GET] [in C:\Users\jrile\AppData\Local\Programs\Python\Python38\lib\site-packages\flask\app.py:1890]
Traceback (most recent call last):
  File "C:\Users\jrile\AppData\Local\Programs\Python\Python38\lib\site-packages\flask\app.py", line 2446, in wsgi_app
    response = self.full_dispatch_request()
  File "C:\Users\jrile\AppData\Local\Programs\Python\Python38\lib\site-packages\flask\app.py", line 1951, in full_dispatch_request
    rv = self.handle_user_exception(e)
  File "C:\Users\jrile\AppData\Local\Programs\Python\Python38\lib\site-packages\flask\app.py", line 1820, in handle_user_exception
    reraise(exc_type, exc_value, tb)
  File "C:\Users\jrile\AppData\Local\Programs\Python\Python38\lib\site-packages\flask\_compat.py", line 39, in reraise
    raise value
  File "C:\Users\jrile\AppData\Local\Programs\Python\Python38\lib\site-packages\flask\app.py", line 1949, in full_dispatch_request
    rv = self.dispatch_request()
  File "C:\Users\jrile\AppData\Local\Programs\Python\Python38\lib\site-packages\flask\app.py", line 1935, in dispatch_request
    return self.view_functions[rule.endpoint](**req.view_args)
  File "C:\Users\jrile\AppData\Local\Programs\Python\Python38\lib\site-packages\flask_login\utils.py", line 272, in decorated_view
    return func(*args, **kwargs)
  File "C:/Users/jrile/Desktop/Software Engineering/HelpInPT/flask-boilerplate/app.py", line 557, in section_page
    section_name = section_name[2]
TypeError: 'NoneType' object is not subscriptable
2020-04-08 13:51:57,356 INFO: errors [in C:/Users/jrile/Desktop/Software Engineering/HelpInPT/flask-boilerplate/app.py:918]
2020-04-08 13:52:57,335 ERROR: Exception on /section/12345/1/None [GET] [in C:\Users\jrile\AppData\Local\Programs\Python\Python38\lib\site-packages\flask\app.py:1890]
Traceback (most recent call last):
  File "C:\Users\jrile\AppData\Local\Programs\Python\Python38\lib\site-packages\flask\app.py", line 2446, in wsgi_app
    response = self.full_dispatch_request()
  File "C:\Users\jrile\AppData\Local\Programs\Python\Python38\lib\site-packages\flask\app.py", line 1951, in full_dispatch_request
    rv = self.handle_user_exception(e)
  File "C:\Users\jrile\AppData\Local\Programs\Python\Python38\lib\site-packages\flask\app.py", line 1820, in handle_user_exception
    reraise(exc_type, exc_value, tb)
  File "C:\Users\jrile\AppData\Local\Programs\Python\Python38\lib\site-packages\flask\_compat.py", line 39, in reraise
    raise value
  File "C:\Users\jrile\AppData\Local\Programs\Python\Python38\lib\site-packages\flask\app.py", line 1949, in full_dispatch_request
    rv = self.dispatch_request()
  File "C:\Users\jrile\AppData\Local\Programs\Python\Python38\lib\site-packages\flask\app.py", line 1935, in dispatch_request
    return self.view_functions[rule.endpoint](**req.view_args)
  File "C:\Users\jrile\AppData\Local\Programs\Python\Python38\lib\site-packages\flask_login\utils.py", line 272, in decorated_view
    return func(*args, **kwargs)
  File "C:/Users/jrile/Desktop/Software Engineering/HelpInPT/flask-boilerplate/app.py", line 557, in section_page
    section_name = section_name[2]
TypeError: 'NoneType' object is not subscriptable
2020-04-08 13:53:09,525 ERROR: Exception on /section/12345/1/None [GET] [in C:\Users\jrile\AppData\Local\Programs\Python\Python38\lib\site-packages\flask\app.py:1890]
Traceback (most recent call last):
  File "C:\Users\jrile\AppData\Local\Programs\Python\Python38\lib\site-packages\flask\app.py", line 2446, in wsgi_app
    response = self.full_dispatch_request()
  File "C:\Users\jrile\AppData\Local\Programs\Python\Python38\lib\site-packages\flask\app.py", line 1951, in full_dispatch_request
    rv = self.handle_user_exception(e)
  File "C:\Users\jrile\AppData\Local\Programs\Python\Python38\lib\site-packages\flask\app.py", line 1820, in handle_user_exception
    reraise(exc_type, exc_value, tb)
  File "C:\Users\jrile\AppData\Local\Programs\Python\Python38\lib\site-packages\flask\_compat.py", line 39, in reraise
    raise value
  File "C:\Users\jrile\AppData\Local\Programs\Python\Python38\lib\site-packages\flask\app.py", line 1949, in full_dispatch_request
    rv = self.dispatch_request()
  File "C:\Users\jrile\AppData\Local\Programs\Python\Python38\lib\site-packages\flask\app.py", line 1935, in dispatch_request
    return self.view_functions[rule.endpoint](**req.view_args)
  File "C:\Users\jrile\AppData\Local\Programs\Python\Python38\lib\site-packages\flask_login\utils.py", line 272, in decorated_view
    return func(*args, **kwargs)
  File "C:/Users/jrile/Desktop/Software Engineering/HelpInPT/flask-boilerplate/app.py", line 557, in section_page
    section_name = section_name[2]
TypeError: 'NoneType' object is not subscriptable
2020-04-08 13:53:58,510 INFO: errors [in C:/Users/jrile/Desktop/Software Engineering/HelpInPT/flask-boilerplate/app.py:918]
