2020-04-15 12:37:47,667 INFO: errors [in C:/Users/jrile/Desktop/Software Engineering/HelpInPT/flask-boilerplate/app.py:1057]
2020-04-15 12:39:05,585 ERROR: Exception on /section/69/3/4 [GET] [in C:\Users\jrile\AppData\Local\Programs\Python\Python38\lib\site-packages\flask\app.py:1890]
Traceback (most recent call last):
  File "C:\Users\jrile\AppData\Local\Programs\Python\Python38\lib\site-packages\flask\app.py", line 2446, in wsgi_app
    response = self.full_dispatch_request()
  File "C:\Users\jrile\AppData\Local\Programs\Python\Python38\lib\site-packages\flask\app.py", line 1951, in full_dispatch_request
    rv = self.handle_user_exception(e)
  File "C:\Users\jrile\AppData\Local\Programs\Python\Python38\lib\site-packages\flask\app.py", line 1820, in handle_user_exception
    reraise(exc_type, exc_value, tb)
  File "C:\Users\jrile\AppData\Local\Programs\Python\Python38\lib\site-packages\flask\_compat.py", line 39, in reraise
    raise value
  File "C:\Users\jrile\AppData\Local\Programs\Python\Python38\lib\site-packages\flask\app.py", line 1949, in full_dispatch_request
    rv = self.dispatch_request()
  File "C:\Users\jrile\AppData\Local\Programs\Python\Python38\lib\site-packages\flask\app.py", line 1935, in dispatch_request
    return self.view_functions[rule.endpoint](**req.view_args)
  File "C:\Users\jrile\AppData\Local\Programs\Python\Python38\lib\site-packages\flask_login\utils.py", line 272, in decorated_view
    return func(*args, **kwargs)
  File "C:/Users/jrile/Desktop/Software Engineering/HelpInPT/flask-boilerplate/app.py", line 685, in section_page
    return render_template('layouts/section.html', chapter=chapter, section=section, q_list=q_list,
  File "C:\Users\jrile\AppData\Local\Programs\Python\Python38\lib\site-packages\flask\templating.py", line 137, in render_template
    return _render(
  File "C:\Users\jrile\AppData\Local\Programs\Python\Python38\lib\site-packages\flask\templating.py", line 120, in _render
    rv = template.render(context)
  File "C:\Users\jrile\AppData\Local\Programs\Python\Python38\lib\site-packages\jinja2\asyncsupport.py", line 76, in render
    return original_render(self, *args, **kwargs)
  File "C:\Users\jrile\AppData\Local\Programs\Python\Python38\lib\site-packages\jinja2\environment.py", line 1008, in render
    return self.environment.handle_exception(exc_info, True)
  File "C:\Users\jrile\AppData\Local\Programs\Python\Python38\lib\site-packages\jinja2\environment.py", line 780, in handle_exception
    reraise(exc_type, exc_value, tb)
  File "C:\Users\jrile\AppData\Local\Programs\Python\Python38\lib\site-packages\jinja2\_compat.py", line 37, in reraise
    raise value.with_traceback(tb)
  File "C:\Users\jrile\Desktop\Software Engineering\HelpInPT\flask-boilerplate\templates\layouts\section.html", line 1, in <module>
    {% extends 'layouts/base' %}
  File "C:\Users\jrile\AppData\Local\Programs\Python\Python38\lib\site-packages\jinja2\environment.py", line 1005, in render
    return concat(self.root_render_func(self.new_context(vars)))
  File "C:\Users\jrile\Desktop\Software Engineering\HelpInPT\flask-boilerplate\templates\layouts\section.html", line 14, in root
    <p>
  File "C:\Users\jrile\Desktop\Software Engineering\HelpInPT\flask-boilerplate\templates\layouts\base", line 52, in root
    width: 100%; /* Full width */
  File "C:\Users\jrile\Desktop\Software Engineering\HelpInPT\flask-boilerplate\templates\layouts\section.html", line 169, in block_content
    <button id="next" class="btn btn-primary next-hidden">Back to Class Overview</button>
  File "C:\Users\jrile\AppData\Local\Programs\Python\Python38\lib\site-packages\jinja2\environment.py", line 411, in getitem
    return obj[argument]
jinja2.exceptions.UndefinedError: list object has no element 0
2020-04-15 12:39:34,228 ERROR: Exception on /section/69/3/4 [GET] [in C:\Users\jrile\AppData\Local\Programs\Python\Python38\lib\site-packages\flask\app.py:1890]
Traceback (most recent call last):
  File "C:\Users\jrile\AppData\Local\Programs\Python\Python38\lib\site-packages\flask\app.py", line 2446, in wsgi_app
    response = self.full_dispatch_request()
  File "C:\Users\jrile\AppData\Local\Programs\Python\Python38\lib\site-packages\flask\app.py", line 1951, in full_dispatch_request
    rv = self.handle_user_exception(e)
  File "C:\Users\jrile\AppData\Local\Programs\Python\Python38\lib\site-packages\flask\app.py", line 1820, in handle_user_exception
    reraise(exc_type, exc_value, tb)
  File "C:\Users\jrile\AppData\Local\Programs\Python\Python38\lib\site-packages\flask\_compat.py", line 39, in reraise
    raise value
  File "C:\Users\jrile\AppData\Local\Programs\Python\Python38\lib\site-packages\flask\app.py", line 1949, in full_dispatch_request
    rv = self.dispatch_request()
  File "C:\Users\jrile\AppData\Local\Programs\Python\Python38\lib\site-packages\flask\app.py", line 1935, in dispatch_request
    return self.view_functions[rule.endpoint](**req.view_args)
  File "C:\Users\jrile\AppData\Local\Programs\Python\Python38\lib\site-packages\flask_login\utils.py", line 272, in decorated_view
    return func(*args, **kwargs)
  File "C:/Users/jrile/Desktop/Software Engineering/HelpInPT/flask-boilerplate/app.py", line 685, in section_page
    return render_template('layouts/section.html', chapter=chapter, section=section, q_list=q_list,
  File "C:\Users\jrile\AppData\Local\Programs\Python\Python38\lib\site-packages\flask\templating.py", line 137, in render_template
    return _render(
  File "C:\Users\jrile\AppData\Local\Programs\Python\Python38\lib\site-packages\flask\templating.py", line 120, in _render
    rv = template.render(context)
  File "C:\Users\jrile\AppData\Local\Programs\Python\Python38\lib\site-packages\jinja2\asyncsupport.py", line 76, in render
    return original_render(self, *args, **kwargs)
  File "C:\Users\jrile\AppData\Local\Programs\Python\Python38\lib\site-packages\jinja2\environment.py", line 1008, in render
    return self.environment.handle_exception(exc_info, True)
  File "C:\Users\jrile\AppData\Local\Programs\Python\Python38\lib\site-packages\jinja2\environment.py", line 780, in handle_exception
    reraise(exc_type, exc_value, tb)
  File "C:\Users\jrile\AppData\Local\Programs\Python\Python38\lib\site-packages\jinja2\_compat.py", line 37, in reraise
    raise value.with_traceback(tb)
  File "C:\Users\jrile\Desktop\Software Engineering\HelpInPT\flask-boilerplate\templates\layouts\section.html", line 1, in <module>
    {% extends 'layouts/base' %}
  File "C:\Users\jrile\AppData\Local\Programs\Python\Python38\lib\site-packages\jinja2\environment.py", line 1005, in render
    return concat(self.root_render_func(self.new_context(vars)))
  File "C:\Users\jrile\Desktop\Software Engineering\HelpInPT\flask-boilerplate\templates\layouts\section.html", line 14, in root
    <p>
  File "C:\Users\jrile\Desktop\Software Engineering\HelpInPT\flask-boilerplate\templates\layouts\base", line 52, in root
    width: 100%; /* Full width */
  File "C:\Users\jrile\Desktop\Software Engineering\HelpInPT\flask-boilerplate\templates\layouts\section.html", line 169, in block_content
    <button id="next" class="btn btn-primary next-hidden">Back to Class Overview</button>
  File "C:\Users\jrile\AppData\Local\Programs\Python\Python38\lib\site-packages\jinja2\environment.py", line 411, in getitem
    return obj[argument]
jinja2.exceptions.UndefinedError: list object has no element 0
2020-04-15 12:40:59,790 ERROR: Exception on /section/69/3/4 [GET] [in C:\Users\jrile\AppData\Local\Programs\Python\Python38\lib\site-packages\flask\app.py:1890]
Traceback (most recent call last):
  File "C:\Users\jrile\AppData\Local\Programs\Python\Python38\lib\site-packages\flask\app.py", line 2446, in wsgi_app
    response = self.full_dispatch_request()
  File "C:\Users\jrile\AppData\Local\Programs\Python\Python38\lib\site-packages\flask\app.py", line 1951, in full_dispatch_request
    rv = self.handle_user_exception(e)
  File "C:\Users\jrile\AppData\Local\Programs\Python\Python38\lib\site-packages\flask\app.py", line 1820, in handle_user_exception
    reraise(exc_type, exc_value, tb)
  File "C:\Users\jrile\AppData\Local\Programs\Python\Python38\lib\site-packages\flask\_compat.py", line 39, in reraise
    raise value
  File "C:\Users\jrile\AppData\Local\Programs\Python\Python38\lib\site-packages\flask\app.py", line 1949, in full_dispatch_request
    rv = self.dispatch_request()
  File "C:\Users\jrile\AppData\Local\Programs\Python\Python38\lib\site-packages\flask\app.py", line 1935, in dispatch_request
    return self.view_functions[rule.endpoint](**req.view_args)
  File "C:\Users\jrile\AppData\Local\Programs\Python\Python38\lib\site-packages\flask_login\utils.py", line 272, in decorated_view
    return func(*args, **kwargs)
  File "C:/Users/jrile/Desktop/Software Engineering/HelpInPT/flask-boilerplate/app.py", line 685, in section_page
    return render_template('layouts/section.html', chapter=chapter, section=section, q_list=q_list,
  File "C:\Users\jrile\AppData\Local\Programs\Python\Python38\lib\site-packages\flask\templating.py", line 137, in render_template
    return _render(
  File "C:\Users\jrile\AppData\Local\Programs\Python\Python38\lib\site-packages\flask\templating.py", line 120, in _render
    rv = template.render(context)
  File "C:\Users\jrile\AppData\Local\Programs\Python\Python38\lib\site-packages\jinja2\asyncsupport.py", line 76, in render
    return original_render(self, *args, **kwargs)
  File "C:\Users\jrile\AppData\Local\Programs\Python\Python38\lib\site-packages\jinja2\environment.py", line 1008, in render
    return self.environment.handle_exception(exc_info, True)
  File "C:\Users\jrile\AppData\Local\Programs\Python\Python38\lib\site-packages\jinja2\environment.py", line 780, in handle_exception
    reraise(exc_type, exc_value, tb)
  File "C:\Users\jrile\AppData\Local\Programs\Python\Python38\lib\site-packages\jinja2\_compat.py", line 37, in reraise
    raise value.with_traceback(tb)
  File "C:\Users\jrile\Desktop\Software Engineering\HelpInPT\flask-boilerplate\templates\layouts\section.html", line 1, in <module>
    {% extends 'layouts/base' %}
  File "C:\Users\jrile\AppData\Local\Programs\Python\Python38\lib\site-packages\jinja2\environment.py", line 1005, in render
    return concat(self.root_render_func(self.new_context(vars)))
  File "C:\Users\jrile\Desktop\Software Engineering\HelpInPT\flask-boilerplate\templates\layouts\section.html", line 14, in root
    <p>
  File "C:\Users\jrile\Desktop\Software Engineering\HelpInPT\flask-boilerplate\templates\layouts\base", line 52, in root
    width: 100%; /* Full width */
  File "C:\Users\jrile\Desktop\Software Engineering\HelpInPT\flask-boilerplate\templates\layouts\section.html", line 169, in block_content
    <button id="next" class="btn btn-primary next-hidden">Back to Class Overview</button>
  File "C:\Users\jrile\AppData\Local\Programs\Python\Python38\lib\site-packages\jinja2\environment.py", line 411, in getitem
    return obj[argument]
jinja2.exceptions.UndefinedError: list object has no element 0
2020-04-15 12:43:44,100 ERROR: Exception on /section/69/3/4 [GET] [in C:\Users\jrile\AppData\Local\Programs\Python\Python38\lib\site-packages\flask\app.py:1890]
Traceback (most recent call last):
  File "C:\Users\jrile\AppData\Local\Programs\Python\Python38\lib\site-packages\flask\app.py", line 2446, in wsgi_app
    response = self.full_dispatch_request()
  File "C:\Users\jrile\AppData\Local\Programs\Python\Python38\lib\site-packages\flask\app.py", line 1951, in full_dispatch_request
    rv = self.handle_user_exception(e)
  File "C:\Users\jrile\AppData\Local\Programs\Python\Python38\lib\site-packages\flask\app.py", line 1820, in handle_user_exception
    reraise(exc_type, exc_value, tb)
  File "C:\Users\jrile\AppData\Local\Programs\Python\Python38\lib\site-packages\flask\_compat.py", line 39, in reraise
    raise value
  File "C:\Users\jrile\AppData\Local\Programs\Python\Python38\lib\site-packages\flask\app.py", line 1949, in full_dispatch_request
    rv = self.dispatch_request()
  File "C:\Users\jrile\AppData\Local\Programs\Python\Python38\lib\site-packages\flask\app.py", line 1935, in dispatch_request
    return self.view_functions[rule.endpoint](**req.view_args)
  File "C:\Users\jrile\AppData\Local\Programs\Python\Python38\lib\site-packages\flask_login\utils.py", line 272, in decorated_view
    return func(*args, **kwargs)
  File "C:/Users/jrile/Desktop/Software Engineering/HelpInPT/flask-boilerplate/app.py", line 685, in section_page
    return render_template('layouts/section.html', chapter=chapter, section=section, q_list=q_list,
  File "C:\Users\jrile\AppData\Local\Programs\Python\Python38\lib\site-packages\flask\templating.py", line 137, in render_template
    return _render(
  File "C:\Users\jrile\AppData\Local\Programs\Python\Python38\lib\site-packages\flask\templating.py", line 120, in _render
    rv = template.render(context)
  File "C:\Users\jrile\AppData\Local\Programs\Python\Python38\lib\site-packages\jinja2\asyncsupport.py", line 76, in render
    return original_render(self, *args, **kwargs)
  File "C:\Users\jrile\AppData\Local\Programs\Python\Python38\lib\site-packages\jinja2\environment.py", line 1008, in render
    return self.environment.handle_exception(exc_info, True)
  File "C:\Users\jrile\AppData\Local\Programs\Python\Python38\lib\site-packages\jinja2\environment.py", line 780, in handle_exception
    reraise(exc_type, exc_value, tb)
  File "C:\Users\jrile\AppData\Local\Programs\Python\Python38\lib\site-packages\jinja2\_compat.py", line 37, in reraise
    raise value.with_traceback(tb)
  File "C:\Users\jrile\Desktop\Software Engineering\HelpInPT\flask-boilerplate\templates\layouts\section.html", line 1, in <module>
    {% extends 'layouts/base' %}
  File "C:\Users\jrile\AppData\Local\Programs\Python\Python38\lib\site-packages\jinja2\environment.py", line 1005, in render
    return concat(self.root_render_func(self.new_context(vars)))
  File "C:\Users\jrile\Desktop\Software Engineering\HelpInPT\flask-boilerplate\templates\layouts\section.html", line 14, in root
    <p>
  File "C:\Users\jrile\Desktop\Software Engineering\HelpInPT\flask-boilerplate\templates\layouts\base", line 52, in root
    width: 100%; /* Full width */
  File "C:\Users\jrile\Desktop\Software Engineering\HelpInPT\flask-boilerplate\templates\layouts\section.html", line 169, in block_content
    <button id="next" class="btn btn-primary next-hidden">Back to Class Overview</button>
  File "C:\Users\jrile\AppData\Local\Programs\Python\Python38\lib\site-packages\jinja2\environment.py", line 411, in getitem
    return obj[argument]
jinja2.exceptions.UndefinedError: list object has no element 0
2020-04-15 12:46:59,864 ERROR: Exception on /section/69/3/4 [GET] [in C:\Users\jrile\AppData\Local\Programs\Python\Python38\lib\site-packages\flask\app.py:1890]
Traceback (most recent call last):
  File "C:\Users\jrile\AppData\Local\Programs\Python\Python38\lib\site-packages\flask\app.py", line 2446, in wsgi_app
    response = self.full_dispatch_request()
  File "C:\Users\jrile\AppData\Local\Programs\Python\Python38\lib\site-packages\flask\app.py", line 1951, in full_dispatch_request
    rv = self.handle_user_exception(e)
  File "C:\Users\jrile\AppData\Local\Programs\Python\Python38\lib\site-packages\flask\app.py", line 1820, in handle_user_exception
    reraise(exc_type, exc_value, tb)
  File "C:\Users\jrile\AppData\Local\Programs\Python\Python38\lib\site-packages\flask\_compat.py", line 39, in reraise
    raise value
  File "C:\Users\jrile\AppData\Local\Programs\Python\Python38\lib\site-packages\flask\app.py", line 1949, in full_dispatch_request
    rv = self.dispatch_request()
  File "C:\Users\jrile\AppData\Local\Programs\Python\Python38\lib\site-packages\flask\app.py", line 1935, in dispatch_request
    return self.view_functions[rule.endpoint](**req.view_args)
  File "C:\Users\jrile\AppData\Local\Programs\Python\Python38\lib\site-packages\flask_login\utils.py", line 272, in decorated_view
    return func(*args, **kwargs)
  File "C:/Users/jrile/Desktop/Software Engineering/HelpInPT/flask-boilerplate/app.py", line 685, in section_page
    return render_template('layouts/section.html', chapter=chapter, section=section, q_list=q_list,
  File "C:\Users\jrile\AppData\Local\Programs\Python\Python38\lib\site-packages\flask\templating.py", line 137, in render_template
    return _render(
  File "C:\Users\jrile\AppData\Local\Programs\Python\Python38\lib\site-packages\flask\templating.py", line 120, in _render
    rv = template.render(context)
  File "C:\Users\jrile\AppData\Local\Programs\Python\Python38\lib\site-packages\jinja2\asyncsupport.py", line 76, in render
    return original_render(self, *args, **kwargs)
  File "C:\Users\jrile\AppData\Local\Programs\Python\Python38\lib\site-packages\jinja2\environment.py", line 1008, in render
    return self.environment.handle_exception(exc_info, True)
  File "C:\Users\jrile\AppData\Local\Programs\Python\Python38\lib\site-packages\jinja2\environment.py", line 780, in handle_exception
    reraise(exc_type, exc_value, tb)
  File "C:\Users\jrile\AppData\Local\Programs\Python\Python38\lib\site-packages\jinja2\_compat.py", line 37, in reraise
    raise value.with_traceback(tb)
  File "C:\Users\jrile\Desktop\Software Engineering\HelpInPT\flask-boilerplate\templates\layouts\section.html", line 1, in <module>
    {% extends 'layouts/base' %}
  File "C:\Users\jrile\AppData\Local\Programs\Python\Python38\lib\site-packages\jinja2\environment.py", line 1005, in render
    return concat(self.root_render_func(self.new_context(vars)))
  File "C:\Users\jrile\Desktop\Software Engineering\HelpInPT\flask-boilerplate\templates\layouts\section.html", line 14, in root
    <p>
  File "C:\Users\jrile\Desktop\Software Engineering\HelpInPT\flask-boilerplate\templates\layouts\base", line 52, in root
    width: 100%; /* Full width */
  File "C:\Users\jrile\Desktop\Software Engineering\HelpInPT\flask-boilerplate\templates\layouts\section.html", line 169, in block_content
    <button id="next" class="btn btn-primary next-hidden">Back to Class Overview</button>
  File "C:\Users\jrile\AppData\Local\Programs\Python\Python38\lib\site-packages\jinja2\environment.py", line 411, in getitem
    return obj[argument]
jinja2.exceptions.UndefinedError: list object has no element 0
2020-04-15 12:57:44,080 INFO: errors [in C:/Users/jrile/Desktop/Software Engineering/HelpInPT/flask-boilerplate/app.py:1057]
2020-04-15 12:59:18,001 ERROR: Exception on /professor-home [GET] [in C:\Users\jrile\AppData\Local\Programs\Python\Python38\lib\site-packages\flask\app.py:1890]
Traceback (most recent call last):
  File "C:\Users\jrile\AppData\Local\Programs\Python\Python38\lib\site-packages\flask\app.py", line 2446, in wsgi_app
    response = self.full_dispatch_request()
  File "C:\Users\jrile\AppData\Local\Programs\Python\Python38\lib\site-packages\flask\app.py", line 1951, in full_dispatch_request
    rv = self.handle_user_exception(e)
  File "C:\Users\jrile\AppData\Local\Programs\Python\Python38\lib\site-packages\flask\app.py", line 1820, in handle_user_exception
    reraise(exc_type, exc_value, tb)
  File "C:\Users\jrile\AppData\Local\Programs\Python\Python38\lib\site-packages\flask\_compat.py", line 39, in reraise
    raise value
  File "C:\Users\jrile\AppData\Local\Programs\Python\Python38\lib\site-packages\flask\app.py", line 1949, in full_dispatch_request
    rv = self.dispatch_request()
  File "C:\Users\jrile\AppData\Local\Programs\Python\Python38\lib\site-packages\flask\app.py", line 1935, in dispatch_request
    return self.view_functions[rule.endpoint](**req.view_args)
  File "C:\Users\jrile\AppData\Local\Programs\Python\Python38\lib\site-packages\flask_login\utils.py", line 272, in decorated_view
    return func(*args, **kwargs)
  File "C:\Users\jrile\AppData\Local\Programs\Python\Python38\lib\site-packages\flask_user\decorators.py", line 143, in decorator
    return view_function(*args, **kwargs)
  File "C:/Users/jrile/Desktop/Software Engineering/HelpInPT/flask-boilerplate/app.py", line 784, in professor_home
    if form_create.submit1.data and form_create.validate() and query_db('SELECT * from Classes where classID="%s"' % form_create.data["class_id"]) == []:
AttributeError: 'CreateClass' object has no attribute 'submit1'
2020-04-15 13:06:18,495 INFO: errors [in C:/Users/jrile/Desktop/Software Engineering/HelpInPT/flask-boilerplate/app.py:1057]
2020-04-15 13:06:56,344 ERROR: Exception on /edit-class/69 [GET] [in C:\Users\jrile\AppData\Local\Programs\Python\Python38\lib\site-packages\flask\app.py:1890]
Traceback (most recent call last):
  File "C:\Users\jrile\AppData\Local\Programs\Python\Python38\lib\site-packages\flask\app.py", line 2446, in wsgi_app
    response = self.full_dispatch_request()
  File "C:\Users\jrile\AppData\Local\Programs\Python\Python38\lib\site-packages\flask\app.py", line 1951, in full_dispatch_request
    rv = self.handle_user_exception(e)
  File "C:\Users\jrile\AppData\Local\Programs\Python\Python38\lib\site-packages\flask\app.py", line 1820, in handle_user_exception
    reraise(exc_type, exc_value, tb)
  File "C:\Users\jrile\AppData\Local\Programs\Python\Python38\lib\site-packages\flask\_compat.py", line 39, in reraise
    raise value
  File "C:\Users\jrile\AppData\Local\Programs\Python\Python38\lib\site-packages\flask\app.py", line 1949, in full_dispatch_request
    rv = self.dispatch_request()
  File "C:\Users\jrile\AppData\Local\Programs\Python\Python38\lib\site-packages\flask\app.py", line 1935, in dispatch_request
    return self.view_functions[rule.endpoint](**req.view_args)
  File "C:\Users\jrile\AppData\Local\Programs\Python\Python38\lib\site-packages\flask_login\utils.py", line 272, in decorated_view
    return func(*args, **kwargs)
  File "C:\Users\jrile\AppData\Local\Programs\Python\Python38\lib\site-packages\flask_user\decorators.py", line 143, in decorator
    return view_function(*args, **kwargs)
  File "C:/Users/jrile/Desktop/Software Engineering/HelpInPT/flask-boilerplate/app.py", line 294, in edit_class
    return render_template('pages/edit-class.html', chapters=chapters, sections=sections_arrays, classID=classID,
  File "C:\Users\jrile\AppData\Local\Programs\Python\Python38\lib\site-packages\flask\templating.py", line 137, in render_template
    return _render(
  File "C:\Users\jrile\AppData\Local\Programs\Python\Python38\lib\site-packages\flask\templating.py", line 120, in _render
    rv = template.render(context)
  File "C:\Users\jrile\AppData\Local\Programs\Python\Python38\lib\site-packages\jinja2\asyncsupport.py", line 76, in render
    return original_render(self, *args, **kwargs)
  File "C:\Users\jrile\AppData\Local\Programs\Python\Python38\lib\site-packages\jinja2\environment.py", line 1008, in render
    return self.environment.handle_exception(exc_info, True)
  File "C:\Users\jrile\AppData\Local\Programs\Python\Python38\lib\site-packages\jinja2\environment.py", line 780, in handle_exception
    reraise(exc_type, exc_value, tb)
  File "C:\Users\jrile\AppData\Local\Programs\Python\Python38\lib\site-packages\jinja2\_compat.py", line 37, in reraise
    raise value.with_traceback(tb)
  File "C:\Users\jrile\Desktop\Software Engineering\HelpInPT\flask-boilerplate\templates\pages\edit-class.html", line 1, in <module>
    {% extends 'layouts/base' %}
  File "C:\Users\jrile\AppData\Local\Programs\Python\Python38\lib\site-packages\jinja2\environment.py", line 1005, in render
    return concat(self.root_render_func(self.new_context(vars)))
  File "C:\Users\jrile\Desktop\Software Engineering\HelpInPT\flask-boilerplate\templates\pages\edit-class.html", line 14, in root
    <div class="modal-content">
  File "C:\Users\jrile\Desktop\Software Engineering\HelpInPT\flask-boilerplate\templates\layouts\base", line 52, in root
    width: 100%; /* Full width */
  File "C:\Users\jrile\Desktop\Software Engineering\HelpInPT\flask-boilerplate\templates\pages\edit-class.html", line 37, in block_content
    <!--form to edit chapter-->
  File "C:\Users\jrile\AppData\Local\Programs\Python\Python38\lib\site-packages\jinja2\environment.py", line 430, in getattr
    return getattr(obj, attribute)
jinja2.exceptions.UndefinedError: 'forms.CreateChapter object' has no attribute 'orderNo'
2020-04-15 13:08:49,940 INFO: errors [in C:/Users/jrile/Desktop/Software Engineering/HelpInPT/flask-boilerplate/app.py:1057]
2020-04-15 13:10:29,649 INFO: errors [in C:/Users/jrile/Desktop/Software Engineering/HelpInPT/flask-boilerplate/app.py:1057]
2020-04-15 13:10:35,444 ERROR: Exception on /edit-class/69 [GET] [in C:\Users\jrile\AppData\Local\Programs\Python\Python38\lib\site-packages\flask\app.py:1890]
Traceback (most recent call last):
  File "C:\Users\jrile\AppData\Local\Programs\Python\Python38\lib\site-packages\flask\app.py", line 2446, in wsgi_app
    response = self.full_dispatch_request()
  File "C:\Users\jrile\AppData\Local\Programs\Python\Python38\lib\site-packages\flask\app.py", line 1951, in full_dispatch_request
    rv = self.handle_user_exception(e)
  File "C:\Users\jrile\AppData\Local\Programs\Python\Python38\lib\site-packages\flask\app.py", line 1820, in handle_user_exception
    reraise(exc_type, exc_value, tb)
  File "C:\Users\jrile\AppData\Local\Programs\Python\Python38\lib\site-packages\flask\_compat.py", line 39, in reraise
    raise value
  File "C:\Users\jrile\AppData\Local\Programs\Python\Python38\lib\site-packages\flask\app.py", line 1949, in full_dispatch_request
    rv = self.dispatch_request()
  File "C:\Users\jrile\AppData\Local\Programs\Python\Python38\lib\site-packages\flask\app.py", line 1935, in dispatch_request
    return self.view_functions[rule.endpoint](**req.view_args)
  File "C:\Users\jrile\AppData\Local\Programs\Python\Python38\lib\site-packages\flask_login\utils.py", line 272, in decorated_view
    return func(*args, **kwargs)
  File "C:\Users\jrile\AppData\Local\Programs\Python\Python38\lib\site-packages\flask_user\decorators.py", line 143, in decorator
    return view_function(*args, **kwargs)
  File "C:/Users/jrile/Desktop/Software Engineering/HelpInPT/flask-boilerplate/app.py", line 267, in edit_class
    if formEdit.submit1.data and formEdit.validate():
AttributeError: 'EditChapter' object has no attribute 'submit1'
2020-04-15 13:11:11,947 INFO: errors [in C:/Users/jrile/Desktop/Software Engineering/HelpInPT/flask-boilerplate/app.py:1057]
2020-04-15 13:13:49,416 INFO: errors [in C:/Users/jrile/Desktop/Software Engineering/HelpInPT/flask-boilerplate/app.py:1060]
2020-04-15 13:15:43,406 INFO: errors [in C:/Users/jrile/Desktop/Software Engineering/HelpInPT/flask-boilerplate/app.py:1060]
2020-04-15 13:19:01,682 INFO: errors [in C:/Users/jrile/Desktop/Software Engineering/HelpInPT/flask-boilerplate/app.py:1062]
2020-04-15 13:19:07,797 ERROR: Exception on /edit-class/69 [GET] [in C:\Users\jrile\AppData\Local\Programs\Python\Python38\lib\site-packages\flask\app.py:1890]
Traceback (most recent call last):
  File "C:\Users\jrile\AppData\Local\Programs\Python\Python38\lib\site-packages\flask\app.py", line 2446, in wsgi_app
    response = self.full_dispatch_request()
  File "C:\Users\jrile\AppData\Local\Programs\Python\Python38\lib\site-packages\flask\app.py", line 1951, in full_dispatch_request
    rv = self.handle_user_exception(e)
  File "C:\Users\jrile\AppData\Local\Programs\Python\Python38\lib\site-packages\flask\app.py", line 1820, in handle_user_exception
    reraise(exc_type, exc_value, tb)
  File "C:\Users\jrile\AppData\Local\Programs\Python\Python38\lib\site-packages\flask\_compat.py", line 39, in reraise
    raise value
  File "C:\Users\jrile\AppData\Local\Programs\Python\Python38\lib\site-packages\flask\app.py", line 1949, in full_dispatch_request
    rv = self.dispatch_request()
  File "C:\Users\jrile\AppData\Local\Programs\Python\Python38\lib\site-packages\flask\app.py", line 1935, in dispatch_request
    return self.view_functions[rule.endpoint](**req.view_args)
  File "C:\Users\jrile\AppData\Local\Programs\Python\Python38\lib\site-packages\flask_login\utils.py", line 272, in decorated_view
    return func(*args, **kwargs)
  File "C:\Users\jrile\AppData\Local\Programs\Python\Python38\lib\site-packages\flask_user\decorators.py", line 143, in decorator
    return view_function(*args, **kwargs)
  File "C:/Users/jrile/Desktop/Software Engineering/HelpInPT/flask-boilerplate/app.py", line 270, in edit_class
    print("Edit form validated?" + formEdit.validate())
TypeError: can only concatenate str (not "bool") to str
2020-04-15 13:19:40,799 INFO: errors [in C:/Users/jrile/Desktop/Software Engineering/HelpInPT/flask-boilerplate/app.py:1062]
2020-04-15 13:20:40,900 INFO: errors [in C:/Users/jrile/Desktop/Software Engineering/HelpInPT/flask-boilerplate/app.py:1062]
2020-04-15 13:22:30,935 INFO: errors [in C:/Users/jrile/Desktop/Software Engineering/HelpInPT/flask-boilerplate/app.py:1062]
2020-04-15 13:22:45,458 ERROR: Exception on /edit-class/69 [POST] [in C:\Users\jrile\AppData\Local\Programs\Python\Python38\lib\site-packages\flask\app.py:1890]
Traceback (most recent call last):
  File "C:\Users\jrile\AppData\Local\Programs\Python\Python38\lib\site-packages\flask\app.py", line 2446, in wsgi_app
    response = self.full_dispatch_request()
  File "C:\Users\jrile\AppData\Local\Programs\Python\Python38\lib\site-packages\flask\app.py", line 1951, in full_dispatch_request
    rv = self.handle_user_exception(e)
  File "C:\Users\jrile\AppData\Local\Programs\Python\Python38\lib\site-packages\flask\app.py", line 1820, in handle_user_exception
    reraise(exc_type, exc_value, tb)
  File "C:\Users\jrile\AppData\Local\Programs\Python\Python38\lib\site-packages\flask\_compat.py", line 39, in reraise
    raise value
  File "C:\Users\jrile\AppData\Local\Programs\Python\Python38\lib\site-packages\flask\app.py", line 1949, in full_dispatch_request
    rv = self.dispatch_request()
  File "C:\Users\jrile\AppData\Local\Programs\Python\Python38\lib\site-packages\flask\app.py", line 1935, in dispatch_request
    return self.view_functions[rule.endpoint](**req.view_args)
  File "C:\Users\jrile\AppData\Local\Programs\Python\Python38\lib\site-packages\flask_login\utils.py", line 272, in decorated_view
    return func(*args, **kwargs)
  File "C:\Users\jrile\AppData\Local\Programs\Python\Python38\lib\site-packages\flask_user\decorators.py", line 143, in decorator
    return view_function(*args, **kwargs)
  File "C:/Users/jrile/Desktop/Software Engineering/HelpInPT/flask-boilerplate/app.py", line 276, in edit_class
    one_chapter.orderNo = formEdit.data["orderNo1"]
AttributeError: 'NoneType' object has no attribute 'orderNo'
2020-04-16 10:59:50,219 INFO: errors [in C:/Users/ashbr/OneDrive/Documents/College/Senior/Capstone/biomechanics-help/app.py:1091]
2020-04-16 11:06:23,473 ERROR: Exception on /login [GET] [in C:\Users\ashbr\AppData\Local\Programs\Python\Python37-32\lib\site-packages\flask\app.py:1891]
Traceback (most recent call last):
  File "C:\Users\ashbr\AppData\Local\Programs\Python\Python37-32\lib\site-packages\flask\app.py", line 2446, in wsgi_app
    response = self.full_dispatch_request()
  File "C:\Users\ashbr\AppData\Local\Programs\Python\Python37-32\lib\site-packages\flask\app.py", line 1951, in full_dispatch_request
    rv = self.handle_user_exception(e)
  File "C:\Users\ashbr\AppData\Local\Programs\Python\Python37-32\lib\site-packages\flask\app.py", line 1820, in handle_user_exception
    reraise(exc_type, exc_value, tb)
  File "C:\Users\ashbr\AppData\Local\Programs\Python\Python37-32\lib\site-packages\flask\_compat.py", line 39, in reraise
    raise value
  File "C:\Users\ashbr\AppData\Local\Programs\Python\Python37-32\lib\site-packages\flask\app.py", line 1949, in full_dispatch_request
    rv = self.dispatch_request()
  File "C:\Users\ashbr\AppData\Local\Programs\Python\Python37-32\lib\site-packages\flask\app.py", line 1935, in dispatch_request
    return self.view_functions[rule.endpoint](**req.view_args)
  File "C:/Users/ashbr/OneDrive/Documents/College/Senior/Capstone/biomechanics-help/app.py", line 937, in login
    return render_template('forms/login.html', form=form, noNav=True)
  File "C:\Users\ashbr\AppData\Local\Programs\Python\Python37-32\lib\site-packages\flask\templating.py", line 140, in render_template
    ctx.app,
  File "C:\Users\ashbr\AppData\Local\Programs\Python\Python37-32\lib\site-packages\flask\templating.py", line 120, in _render
    rv = template.render(context)
  File "C:\Users\ashbr\AppData\Local\Programs\Python\Python37-32\lib\site-packages\jinja2\environment.py", line 1090, in render
    self.environment.handle_exception()
  File "C:\Users\ashbr\AppData\Local\Programs\Python\Python37-32\lib\site-packages\jinja2\environment.py", line 832, in handle_exception
    reraise(*rewrite_traceback_stack(source=source))
  File "C:\Users\ashbr\AppData\Local\Programs\Python\Python37-32\lib\site-packages\jinja2\_compat.py", line 28, in reraise
    raise value.with_traceback(tb)
  File "C:\Users\ashbr\OneDrive\Documents\College\Senior\Capstone\biomechanics-help\templates\forms\login.html", line 1, in top-level template code
    {% extends 'layouts/base' %}
  File "C:\Users\ashbr\AppData\Local\Programs\Python\Python37-32\lib\site-packages\jinja2\environment.py", line 832, in handle_exception
    reraise(*rewrite_traceback_stack(source=source))
  File "C:\Users\ashbr\AppData\Local\Programs\Python\Python37-32\lib\site-packages\jinja2\_compat.py", line 28, in reraise
    raise value.with_traceback(tb)
  File "C:\Users\ashbr\OneDrive\Documents\College\Senior\Capstone\biomechanics-help\templates\layouts\base", line 153, in template
    <!--similar lines but if signed in as prof vs signed in as student getting different dashboards for the about page-->
jinja2.exceptions.TemplateSyntaxError: unexpected '<'
2020-04-16 11:06:28,960 ERROR: Exception on /login [GET] [in C:\Users\ashbr\AppData\Local\Programs\Python\Python37-32\lib\site-packages\flask\app.py:1891]
Traceback (most recent call last):
  File "C:\Users\ashbr\AppData\Local\Programs\Python\Python37-32\lib\site-packages\flask\app.py", line 2446, in wsgi_app
    response = self.full_dispatch_request()
  File "C:\Users\ashbr\AppData\Local\Programs\Python\Python37-32\lib\site-packages\flask\app.py", line 1951, in full_dispatch_request
    rv = self.handle_user_exception(e)
  File "C:\Users\ashbr\AppData\Local\Programs\Python\Python37-32\lib\site-packages\flask\app.py", line 1820, in handle_user_exception
    reraise(exc_type, exc_value, tb)
  File "C:\Users\ashbr\AppData\Local\Programs\Python\Python37-32\lib\site-packages\flask\_compat.py", line 39, in reraise
    raise value
  File "C:\Users\ashbr\AppData\Local\Programs\Python\Python37-32\lib\site-packages\flask\app.py", line 1949, in full_dispatch_request
    rv = self.dispatch_request()
  File "C:\Users\ashbr\AppData\Local\Programs\Python\Python37-32\lib\site-packages\flask\app.py", line 1935, in dispatch_request
    return self.view_functions[rule.endpoint](**req.view_args)
  File "C:/Users/ashbr/OneDrive/Documents/College/Senior/Capstone/biomechanics-help/app.py", line 937, in login
    return render_template('forms/login.html', form=form, noNav=True)
  File "C:\Users\ashbr\AppData\Local\Programs\Python\Python37-32\lib\site-packages\flask\templating.py", line 140, in render_template
    ctx.app,
  File "C:\Users\ashbr\AppData\Local\Programs\Python\Python37-32\lib\site-packages\flask\templating.py", line 120, in _render
    rv = template.render(context)
  File "C:\Users\ashbr\AppData\Local\Programs\Python\Python37-32\lib\site-packages\jinja2\environment.py", line 1090, in render
    self.environment.handle_exception()
  File "C:\Users\ashbr\AppData\Local\Programs\Python\Python37-32\lib\site-packages\jinja2\environment.py", line 832, in handle_exception
    reraise(*rewrite_traceback_stack(source=source))
  File "C:\Users\ashbr\AppData\Local\Programs\Python\Python37-32\lib\site-packages\jinja2\_compat.py", line 28, in reraise
    raise value.with_traceback(tb)
  File "C:\Users\ashbr\OneDrive\Documents\College\Senior\Capstone\biomechanics-help\templates\forms\login.html", line 1, in top-level template code
    {% extends 'layouts/base' %}
  File "C:\Users\ashbr\AppData\Local\Programs\Python\Python37-32\lib\site-packages\jinja2\environment.py", line 832, in handle_exception
    reraise(*rewrite_traceback_stack(source=source))
  File "C:\Users\ashbr\AppData\Local\Programs\Python\Python37-32\lib\site-packages\jinja2\_compat.py", line 28, in reraise
    raise value.with_traceback(tb)
  File "C:\Users\ashbr\OneDrive\Documents\College\Senior\Capstone\biomechanics-help\templates\layouts\base", line 153, in template
    <!--similar lines but if signed in as prof vs signed in as student getting different dashboards for the about page-->
jinja2.exceptions.TemplateSyntaxError: unexpected '<'
2020-04-16 11:06:41,318 ERROR: Exception on /login [GET] [in C:\Users\ashbr\AppData\Local\Programs\Python\Python37-32\lib\site-packages\flask\app.py:1891]
Traceback (most recent call last):
  File "C:\Users\ashbr\AppData\Local\Programs\Python\Python37-32\lib\site-packages\flask\app.py", line 2446, in wsgi_app
    response = self.full_dispatch_request()
  File "C:\Users\ashbr\AppData\Local\Programs\Python\Python37-32\lib\site-packages\flask\app.py", line 1951, in full_dispatch_request
    rv = self.handle_user_exception(e)
  File "C:\Users\ashbr\AppData\Local\Programs\Python\Python37-32\lib\site-packages\flask\app.py", line 1820, in handle_user_exception
    reraise(exc_type, exc_value, tb)
  File "C:\Users\ashbr\AppData\Local\Programs\Python\Python37-32\lib\site-packages\flask\_compat.py", line 39, in reraise
    raise value
  File "C:\Users\ashbr\AppData\Local\Programs\Python\Python37-32\lib\site-packages\flask\app.py", line 1949, in full_dispatch_request
    rv = self.dispatch_request()
  File "C:\Users\ashbr\AppData\Local\Programs\Python\Python37-32\lib\site-packages\flask\app.py", line 1935, in dispatch_request
    return self.view_functions[rule.endpoint](**req.view_args)
  File "C:/Users/ashbr/OneDrive/Documents/College/Senior/Capstone/biomechanics-help/app.py", line 937, in login
    return render_template('forms/login.html', form=form, noNav=True)
  File "C:\Users\ashbr\AppData\Local\Programs\Python\Python37-32\lib\site-packages\flask\templating.py", line 140, in render_template
    ctx.app,
  File "C:\Users\ashbr\AppData\Local\Programs\Python\Python37-32\lib\site-packages\flask\templating.py", line 120, in _render
    rv = template.render(context)
  File "C:\Users\ashbr\AppData\Local\Programs\Python\Python37-32\lib\site-packages\jinja2\environment.py", line 1090, in render
    self.environment.handle_exception()
  File "C:\Users\ashbr\AppData\Local\Programs\Python\Python37-32\lib\site-packages\jinja2\environment.py", line 832, in handle_exception
    reraise(*rewrite_traceback_stack(source=source))
  File "C:\Users\ashbr\AppData\Local\Programs\Python\Python37-32\lib\site-packages\jinja2\_compat.py", line 28, in reraise
    raise value.with_traceback(tb)
  File "C:\Users\ashbr\OneDrive\Documents\College\Senior\Capstone\biomechanics-help\templates\forms\login.html", line 1, in top-level template code
    {% extends 'layouts/base' %}
  File "C:\Users\ashbr\AppData\Local\Programs\Python\Python37-32\lib\site-packages\jinja2\environment.py", line 832, in handle_exception
    reraise(*rewrite_traceback_stack(source=source))
  File "C:\Users\ashbr\AppData\Local\Programs\Python\Python37-32\lib\site-packages\jinja2\_compat.py", line 28, in reraise
    raise value.with_traceback(tb)
  File "C:\Users\ashbr\OneDrive\Documents\College\Senior\Capstone\biomechanics-help\templates\layouts\base", line 153, in template
    <!--similar lines but if signed in as prof vs signed in as student getting different dashboards for the about page-->
jinja2.exceptions.TemplateSyntaxError: unexpected '<'
2020-04-16 11:25:19,970 INFO: errors [in C:/Users/ashbr/OneDrive/Documents/College/Senior/Capstone/biomechanics-help/app.py:1094]
2020-04-16 11:26:45,769 INFO: errors [in C:/Users/ashbr/OneDrive/Documents/College/Senior/Capstone/biomechanics-help/app.py:1094]
2020-04-16 11:27:55,574 INFO: errors [in C:/Users/ashbr/OneDrive/Documents/College/Senior/Capstone/biomechanics-help/app.py:1094]
2020-04-16 11:28:38,621 INFO: errors [in C:/Users/ashbr/OneDrive/Documents/College/Senior/Capstone/biomechanics-help/app.py:1094]
2020-04-16 11:29:16,092 INFO: errors [in C:/Users/ashbr/OneDrive/Documents/College/Senior/Capstone/biomechanics-help/app.py:1094]
2020-04-16 11:29:37,958 INFO: errors [in C:/Users/ashbr/OneDrive/Documents/College/Senior/Capstone/biomechanics-help/app.py:1094]
2020-04-16 11:29:56,006 INFO: errors [in C:/Users/ashbr/OneDrive/Documents/College/Senior/Capstone/biomechanics-help/app.py:1094]
2020-04-16 11:30:35,582 INFO: errors [in C:/Users/ashbr/OneDrive/Documents/College/Senior/Capstone/biomechanics-help/app.py:1094]
2020-04-16 11:31:15,119 INFO: errors [in C:/Users/ashbr/OneDrive/Documents/College/Senior/Capstone/biomechanics-help/app.py:1094]
2020-04-16 11:31:47,693 INFO: errors [in C:/Users/ashbr/OneDrive/Documents/College/Senior/Capstone/biomechanics-help/app.py:1094]
2020-04-16 11:32:45,005 INFO: errors [in C:/Users/ashbr/OneDrive/Documents/College/Senior/Capstone/biomechanics-help/app.py:1094]
2020-04-16 11:33:12,282 INFO: errors [in C:/Users/ashbr/OneDrive/Documents/College/Senior/Capstone/biomechanics-help/app.py:1094]
2020-04-16 11:33:45,591 INFO: errors [in C:/Users/ashbr/OneDrive/Documents/College/Senior/Capstone/biomechanics-help/app.py:1094]
2020-04-16 11:36:14,796 INFO: errors [in C:/Users/ashbr/OneDrive/Documents/College/Senior/Capstone/biomechanics-help/app.py:1094]
2020-04-16 11:38:07,667 INFO: errors [in C:/Users/ashbr/OneDrive/Documents/College/Senior/Capstone/biomechanics-help/app.py:1094]
2020-04-16 11:38:54,041 INFO: errors [in C:/Users/ashbr/OneDrive/Documents/College/Senior/Capstone/biomechanics-help/app.py:1094]
2020-04-16 11:39:52,265 INFO: errors [in C:/Users/ashbr/OneDrive/Documents/College/Senior/Capstone/biomechanics-help/app.py:1096]
2020-04-16 11:42:28,368 INFO: errors [in C:/Users/ashbr/OneDrive/Documents/College/Senior/Capstone/biomechanics-help/app.py:1096]
2020-04-16 11:59:24,428 INFO: errors [in C:/Users/ashbr/OneDrive/Documents/College/Senior/Capstone/biomechanics-help/app.py:1091]
2020-04-16 12:02:47,325 INFO: errors [in C:/Users/ashbr/OneDrive/Documents/College/Senior/Capstone/biomechanics-help/app.py:1094]
2020-04-18 05:16:53,927 INFO: errors [in /Users/ricardo/Documents/GitHub/biomechanics-help/app.py:1099]
2020-04-18 05:19:02,387 INFO: errors [in /Users/ricardo/Documents/GitHub/biomechanics-help/app.py:1099]
2020-04-18 05:19:54,681 INFO: errors [in /Users/ricardo/Documents/GitHub/biomechanics-help/app.py:1099]
2020-04-18 06:19:07,402 INFO: errors [in /Users/ricardo/Documents/GitHub/biomechanics-help/app.py:1100]
2020-04-18 06:19:09,768 ERROR: Exception on /professor-home [GET] [in /Library/Frameworks/Python.framework/Versions/3.8/lib/python3.8/site-packages/flask/app.py:1890]
Traceback (most recent call last):
  File "/Library/Frameworks/Python.framework/Versions/3.8/lib/python3.8/site-packages/flask/app.py", line 2446, in wsgi_app
    response = self.full_dispatch_request()
  File "/Library/Frameworks/Python.framework/Versions/3.8/lib/python3.8/site-packages/flask/app.py", line 1951, in full_dispatch_request
    rv = self.handle_user_exception(e)
  File "/Library/Frameworks/Python.framework/Versions/3.8/lib/python3.8/site-packages/flask/app.py", line 1820, in handle_user_exception
    reraise(exc_type, exc_value, tb)
  File "/Library/Frameworks/Python.framework/Versions/3.8/lib/python3.8/site-packages/flask/_compat.py", line 39, in reraise
    raise value
  File "/Library/Frameworks/Python.framework/Versions/3.8/lib/python3.8/site-packages/flask/app.py", line 1949, in full_dispatch_request
    rv = self.dispatch_request()
  File "/Library/Frameworks/Python.framework/Versions/3.8/lib/python3.8/site-packages/flask/app.py", line 1935, in dispatch_request
    return self.view_functions[rule.endpoint](**req.view_args)
  File "/Library/Frameworks/Python.framework/Versions/3.8/lib/python3.8/site-packages/flask_login/utils.py", line 272, in decorated_view
    return func(*args, **kwargs)
  File "/Library/Frameworks/Python.framework/Versions/3.8/lib/python3.8/site-packages/flask_user/decorators.py", line 143, in decorator
    return view_function(*args, **kwargs)
  File "/Users/ricardo/Documents/GitHub/biomechanics-help/app.py", line 836, in professor_home
    if form_edit.newClassID.data is not None and form_edit.validate_on_submit():
NameError: name 'form_edit' is not defined
2020-04-18 06:19:14,960 ERROR: Exception on /professor-home [GET] [in /Library/Frameworks/Python.framework/Versions/3.8/lib/python3.8/site-packages/flask/app.py:1890]
Traceback (most recent call last):
  File "/Library/Frameworks/Python.framework/Versions/3.8/lib/python3.8/site-packages/flask/app.py", line 2446, in wsgi_app
    response = self.full_dispatch_request()
  File "/Library/Frameworks/Python.framework/Versions/3.8/lib/python3.8/site-packages/flask/app.py", line 1951, in full_dispatch_request
    rv = self.handle_user_exception(e)
  File "/Library/Frameworks/Python.framework/Versions/3.8/lib/python3.8/site-packages/flask/app.py", line 1820, in handle_user_exception
    reraise(exc_type, exc_value, tb)
  File "/Library/Frameworks/Python.framework/Versions/3.8/lib/python3.8/site-packages/flask/_compat.py", line 39, in reraise
    raise value
  File "/Library/Frameworks/Python.framework/Versions/3.8/lib/python3.8/site-packages/flask/app.py", line 1949, in full_dispatch_request
    rv = self.dispatch_request()
  File "/Library/Frameworks/Python.framework/Versions/3.8/lib/python3.8/site-packages/flask/app.py", line 1935, in dispatch_request
    return self.view_functions[rule.endpoint](**req.view_args)
  File "/Library/Frameworks/Python.framework/Versions/3.8/lib/python3.8/site-packages/flask_login/utils.py", line 272, in decorated_view
    return func(*args, **kwargs)
  File "/Library/Frameworks/Python.framework/Versions/3.8/lib/python3.8/site-packages/flask_user/decorators.py", line 143, in decorator
    return view_function(*args, **kwargs)
  File "/Users/ricardo/Documents/GitHub/biomechanics-help/app.py", line 836, in professor_home
    if form_edit.newClassID.data is not None and form_edit.validate_on_submit():
NameError: name 'form_edit' is not defined
2020-04-18 06:19:33,727 INFO: errors [in /Users/ricardo/Documents/GitHub/biomechanics-help/app.py:1100]
2020-04-18 06:19:36,780 ERROR: Exception on /professor-home [GET] [in /Library/Frameworks/Python.framework/Versions/3.8/lib/python3.8/site-packages/flask/app.py:1890]
Traceback (most recent call last):
  File "/Library/Frameworks/Python.framework/Versions/3.8/lib/python3.8/site-packages/flask/app.py", line 2446, in wsgi_app
    response = self.full_dispatch_request()
  File "/Library/Frameworks/Python.framework/Versions/3.8/lib/python3.8/site-packages/flask/app.py", line 1951, in full_dispatch_request
    rv = self.handle_user_exception(e)
  File "/Library/Frameworks/Python.framework/Versions/3.8/lib/python3.8/site-packages/flask/app.py", line 1820, in handle_user_exception
    reraise(exc_type, exc_value, tb)
  File "/Library/Frameworks/Python.framework/Versions/3.8/lib/python3.8/site-packages/flask/_compat.py", line 39, in reraise
    raise value
  File "/Library/Frameworks/Python.framework/Versions/3.8/lib/python3.8/site-packages/flask/app.py", line 1949, in full_dispatch_request
    rv = self.dispatch_request()
  File "/Library/Frameworks/Python.framework/Versions/3.8/lib/python3.8/site-packages/flask/app.py", line 1935, in dispatch_request
    return self.view_functions[rule.endpoint](**req.view_args)
  File "/Library/Frameworks/Python.framework/Versions/3.8/lib/python3.8/site-packages/flask_login/utils.py", line 272, in decorated_view
    return func(*args, **kwargs)
  File "/Library/Frameworks/Python.framework/Versions/3.8/lib/python3.8/site-packages/flask_user/decorators.py", line 143, in decorator
    return view_function(*args, **kwargs)
  File "/Users/ricardo/Documents/GitHub/biomechanics-help/app.py", line 836, in professor_home
    if form_edit.newClassID.data is not None and form_edit.validate_on_submit():
NameError: name 'form_edit' is not defined
2020-04-18 06:19:59,896 INFO: errors [in /Users/ricardo/Documents/GitHub/biomechanics-help/app.py:1100]
2020-04-18 06:20:03,858 ERROR: Exception on /professor-home [GET] [in /Library/Frameworks/Python.framework/Versions/3.8/lib/python3.8/site-packages/flask/app.py:1890]
Traceback (most recent call last):
  File "/Library/Frameworks/Python.framework/Versions/3.8/lib/python3.8/site-packages/flask/app.py", line 2446, in wsgi_app
    response = self.full_dispatch_request()
  File "/Library/Frameworks/Python.framework/Versions/3.8/lib/python3.8/site-packages/flask/app.py", line 1951, in full_dispatch_request
    rv = self.handle_user_exception(e)
  File "/Library/Frameworks/Python.framework/Versions/3.8/lib/python3.8/site-packages/flask/app.py", line 1820, in handle_user_exception
    reraise(exc_type, exc_value, tb)
  File "/Library/Frameworks/Python.framework/Versions/3.8/lib/python3.8/site-packages/flask/_compat.py", line 39, in reraise
    raise value
  File "/Library/Frameworks/Python.framework/Versions/3.8/lib/python3.8/site-packages/flask/app.py", line 1949, in full_dispatch_request
    rv = self.dispatch_request()
  File "/Library/Frameworks/Python.framework/Versions/3.8/lib/python3.8/site-packages/flask/app.py", line 1935, in dispatch_request
    return self.view_functions[rule.endpoint](**req.view_args)
  File "/Library/Frameworks/Python.framework/Versions/3.8/lib/python3.8/site-packages/flask_login/utils.py", line 272, in decorated_view
    return func(*args, **kwargs)
  File "/Library/Frameworks/Python.framework/Versions/3.8/lib/python3.8/site-packages/flask_user/decorators.py", line 143, in decorator
    return view_function(*args, **kwargs)
  File "/Users/ricardo/Documents/GitHub/biomechanics-help/app.py", line 836, in professor_home
    if formEdit.newClassID.data is not None and formEdit.validate_on_submit():
AttributeError: 'EditClass' object has no attribute 'newClassID'
2020-04-18 06:21:11,740 INFO: errors [in /Users/ricardo/Documents/GitHub/biomechanics-help/app.py:1100]
2020-04-18 06:21:43,243 INFO: errors [in /Users/ricardo/Documents/GitHub/biomechanics-help/app.py:1100]
2020-04-18 06:25:04,800 INFO: errors [in /Users/ricardo/Documents/GitHub/biomechanics-help/app.py:1100]
2020-04-18 06:28:34,463 INFO: errors [in /Users/ricardo/Documents/GitHub/biomechanics-help/app.py:1100]
2020-04-18 06:37:21,333 INFO: errors [in /Users/ricardo/Documents/GitHub/biomechanics-help/app.py:1100]
2020-04-18 06:38:02,835 INFO: errors [in /Users/ricardo/Documents/GitHub/biomechanics-help/app.py:1100]
2020-04-18 06:39:19,663 INFO: errors [in /Users/ricardo/Documents/GitHub/biomechanics-help/app.py:1100]
2020-04-18 06:40:18,124 INFO: errors [in /Users/ricardo/Documents/GitHub/biomechanics-help/app.py:1100]
2020-04-18 06:46:12,920 INFO: errors [in /Users/ricardo/Documents/GitHub/biomechanics-help/app.py:1102]
2020-04-18 06:49:33,761 INFO: errors [in /Users/ricardo/Documents/GitHub/biomechanics-help/app.py:1102]
2020-04-18 06:50:17,569 INFO: errors [in /Users/ricardo/Documents/GitHub/biomechanics-help/app.py:1102]
2020-04-18 06:50:46,047 INFO: errors [in /Users/ricardo/Documents/GitHub/biomechanics-help/app.py:1102]
2020-04-18 06:52:00,676 INFO: errors [in /Users/ricardo/Documents/GitHub/biomechanics-help/app.py:1103]
2020-04-18 06:52:38,406 INFO: errors [in /Users/ricardo/Documents/GitHub/biomechanics-help/app.py:1103]
